Workbook

Sheet Instructions
B2: Payment Review Tracker — User Guide
B3: WorkSafeBC Payment Review & Compliance | 2024
B6: PURPOSE
B7: What this tracker does | C7: Monitors monthly pension and allowance payments for 15 claimants across 12 months. Automatically flags discrepancies, missed payments, and late payments using Excel formulas and conditional formatting.
B9: SHEETS
B10: Payment Log | C10: Master data entry sheet. One row per claimant per month. Enter actual payment amounts and statuses here.
B11: Claimant Summary | C11: Auto-calculated pivot-style summary per claimant using SUMIF/COUNTIF formulas. Shows totals, discrepancy counts, and risk level.
B12: Monthly Dashboard | C12: Month-by-month KPIs: total disbursed, flag count, compliance rate. Includes charts.
B13: Discrepancy Register | C13: Filtered view of all non-Paid transactions using Excel formulas. Review queue for the compliance team.
B15: HOW TO USE
B16: Step 1 | C16: Go to Payment Log. Review pre-loaded 2024 data or replace with real data.
B17: Step 2 | C17: Discrepancy column auto-calculates (Actual - Expected). Red = overpayment, blue = underpayment.
B18: Step 3 | C18: Check Claimant Summary for high-risk claimants (2+ flags).
B19: Step 4 | C19: Use Discrepancy Register as your daily review queue — filter by month or status.
B20: Step 5 | C20: Run VBA macros (Alt+F8) to auto-format, generate letters list, or export flagged records.
B22: KEY FORMULAS USED
B23: SUMIF | C23: Aggregates payments per claimant or month
B24: COUNTIF / COUNTIFS | C24: Counts flags, statuses, and discrepancies
B25: IF + AND | C25: Determines risk level based on flag count thresholds
B26: IFERROR | C26: Prevents #DIV/0! and #N/A errors in summary calculations
B27: Conditional Formatting | C27: Color-codes status cells and discrepancy amounts automatically

Sheet Payment Log
A1: Payment Log — 2024 Monthly Payment Records
A2: All amounts in CAD. Discrepancy = Actual – Expected. Negative = underpayment. Positive = overpayment.
A3: Claimant ID | B3: Claimant Name | C3: Type | D3: Month | E3: Month # | F3: Expected ($) | G3: Actual ($) | H3: Discrepancy ($) | I3: Status | J3: Reviewed By | K3: Notes
A4: P001 | B4: Margaret Allen | C4: Pension | D4: Jan | E4: 1 | F4: 2122.49 | G4: 2122.49 | H4: =G4-F4 | I4: Paid | J4: EMP04
A5: P001 | B5: Margaret Allen | C5: Pension | D5: Feb | E5: 2 | F5: 2122.49 | G5: 2122.49 | H5: =G5-F5 | I5: Paid | J5: EMP01
A6: P001 | B6: Margaret Allen | C6: Pension | D6: Mar | E6: 3 | F6: 2122.49 | G6: 1141.16 | H6: =G6-F6 | I6: Under Review | J6: EMP05 | K6: Awaiting confirmation
A7: P001 | B7: Margaret Allen | C7: Pension | D7: Apr | E7: 4 | F7: 2122.49 | G7: 2122.49 | H7: =G7-F7 | I7: Paid | J7: EMP05
A8: P001 | B8: Margaret Allen | C8: Pension | D8: May | E8: 5 | F8: 2122.49 | G8: 2122.49 | H8: =G8-F8 | I8: Paid | J8: EMP01
A9: P001 | B9: Margaret Allen | C9: Pension | D9: Jun | E9: 6 | F9: 2122.49 | G9: 2122.49 | H9: =G9-F9 | I9: Paid | J9: EMP04
A10: P001 | B10: Margaret Allen | C10: Pension | D10: Jul | E10: 7 | F10: 2122.49 | G10: 2122.49 | H10: =G10-F10 | I10: Late | J10: EMP01
A11: P001 | B11: Margaret Allen | C11: Pension | D11: Aug | E11: 8 | F11: 2122.49 | G11: 2122.49 | H11: =G11-F11 | I11: Paid | J11: EMP01
A12: P001 | B12: Margaret Allen | C12: Pension | D12: Sep | E12: 9 | F12: 2122.49 | G12: 1421.66 | H12: =G12-F12 | I12: Under Review | J12: EMP05 | K12: Awaiting confirmation
A13: P001 | B13: Margaret Allen | C13: Pension | D13: Oct | E13: 10 | F13: 2122.49 | G13: 2122.49 | H13: =G13-F13 | I13: Paid | J13: EMP02
A14: P001 | B14: Margaret Allen | C14: Pension | D14: Nov | E14: 11 | F14: 2122.49 | G14: 2837.61 | H14: =G14-F14 | I14: Discrepancy | J14: EMP05 | K14: Awaiting confirmation
A15: P001 | B15: Margaret Allen | C15: Pension | D15: Dec | E15: 12 | F15: 2122.49 | G15: 2545.23 | H15: =G15-F15 | I15: Discrepancy | J15: EMP02 | K15: Awaiting confirmation
A16: P002 | B16: Robert Nguyen | C16: Pension | D16: Jan | E16: 1 | F16: 2000.5 | G16: 2000.5 | H16: =G16-F16 | I16: Paid | J16: EMP03
A17: P002 | B17: Robert Nguyen | C17: Pension | D17: Feb | E17: 2 | F17: 2000.5 | G17: 2000.5 | H17: =G17-F17 | I17: Late | J17: EMP02
A18: P002 | B18: Robert Nguyen | C18: Pension | D18: Mar | E18: 3 | F18: 2000.5 | G18: 1094.51 | H18: =G18-F18 | I18: Under Review | J18: EMP03 | K18: Awaiting confirmation
A19: P002 | B19: Robert Nguyen | C19: Pension | D19: Apr | E19: 4 | F19: 2000.5 | G19: 1653.31 | H19: =G19-F19 | I19: Under Review | J19: EMP02 | K19: Awaiting confirmation
A20: P002 | B20: Robert Nguyen | C20: Pension | D20: May | E20: 5 | F20: 2000.5 | G20: 2000.5 | H20: =G20-F20 | I20: Paid | J20: EMP05
A21: P002 | B21: Robert Nguyen | C21: Pension | D21: Jun | E21: 6 | F21: 2000.5 | G21: 2520.09 | H21: =G21-F21 | I21: Discrepancy | J21: EMP03 | K21: Awaiting confirmation
A22: P002 | B22: Robert Nguyen | C22: Pension | D22: Jul | E22: 7 | F22: 2000.5 | G22: 2000.5 | H22: =G22-F22 | I22: Paid | J22: EMP05
A23: P002 | B23: Robert Nguyen | C23: Pension | D23: Aug | E23: 8 | F23: 2000.5 | G23: 2000.5 | H23: =G23-F23 | I23: Paid | J23: EMP05
A24: P002 | B24: Robert Nguyen | C24: Pension | D24: Sep | E24: 9 | F24: 2000.5 | G24: 2000.5 | H24: =G24-F24 | I24: Paid | J24: EMP05
A25: P002 | B25: Robert Nguyen | C25: Pension | D25: Oct | E25: 10 | F25: 2000.5 | G25: 2000.5 | H25: =G25-F25 | I25: Paid | J25: EMP04
A26: P002 | B26: Robert Nguyen | C26: Pension | D26: Nov | E26: 11 | F26: 2000.5 | G26: 1342.41 | H26: =G26-F26 | I26: Under Review | J26: EMP03 | K26: Awaiting confirmation
A27: P002 | B27: Robert Nguyen | C27: Pension | D27: Dec | E27: 12 | F27: 2000.5 | G27: 0 | H27: =G27-F27 | I27: Missed | J27: EMP05
A28: P003 | B28: Susan Park | C28: Allowance | D28: Jan | E28: 1 | F28: 1572.8 | G28: 1572.8 | H28: =G28-F28 | I28: Paid | J28: EMP03
A29: P003 | B29: Susan Park | C29: Allowance | D29: Feb | E29: 2 | F29: 1572.8 | G29: 1572.8 | H29: =G29-F29 | I29: Paid | J29: EMP02
A30: P003 | B30: Susan Park | C30: Allowance | D30: Mar | E30: 3 | F30: 1572.8 | G30: 1572.8 | H30: =G30-F30 | I30: Paid | J30: EMP01
A31: P003 | B31: Susan Park | C31: Allowance | D31: Apr | E31: 4 | F31: 1572.8 | G31: 1848.14 | H31: =G31-F31 | I31: Discrepancy | J31: EMP04 | K31: Awaiting confirmation
A32: P003 | B32: Susan Park | C32: Allowance | D32: May | E32: 5 | F32: 1572.8 | G32: 1572.8 | H32: =G32-F32 | I32: Paid | J32: EMP04
A33: P003 | B33: Susan Park | C33: Allowance | D33: Jun | E33: 6 | F33: 1572.8 | G33: 1572.8 | H33: =G33-F33 | I33: Paid | J33: EMP05
A34: P003 | B34: Susan Park | C34: Allowance | D34: Jul | E34: 7 | F34: 1572.8 | G34: 1572.8 | H34: =G34-F34 | I34: Paid | J34: EMP01
A35: P003 | B35: Susan Park | C35: Allowance | D35: Aug | E35: 8 | F35: 1572.8 | G35: 1049.45 | H35: =G35-F35 | I35: Under Review | J35: EMP03 | K35: Awaiting confirmation
A36: P003 | B36: Susan Park | C36: Allowance | D36: Sep | E36: 9 | F36: 1572.8 | G36: 1572.8 | H36: =G36-F36 | I36: Paid | J36: EMP04
A37: P003 | B37: Susan Park | C37: Allowance | D37: Oct | E37: 10 | F37: 1572.8 | G37: 1572.8 | H37: =G37-F37 | I37: Late | J37: EMP01
A38: P003 | B38: Susan Park | C38: Allowance | D38: Nov | E38: 11 | F38: 1572.8 | G38: 1572.8 | H38: =G38-F38 | I38: Paid | J38: EMP05
A39: P003 | B39: Susan Park | C39: Allowance | D39: Dec | E39: 12 | F39: 1572.8 | G39: 2040.35 | H39: =G39-F39 | I39: Discrepancy | J39: EMP03 | K39: Awaiting confirmation
A40: P004 | B40: David Kim | C40: Pension | D40: Jan | E40: 1 | F40: 2129.65 | G40: 2129.65 | H40: =G40-F40 | I40: Paid | J40: EMP05
...

Sheet Claimant Summary
A1: Claimant Summary — Annual Payment Review
A2: Formulas pull from Payment Log. Risk Level: HIGH = 3+ flags | MEDIUM = 1-2 flags | LOW = 0 flags
A3: Claimant ID | B3: Claimant Name | C3: Type | D3: Total Expected ($) | E3: Total Actual ($) | F3: Net Discrepancy ($) | G3: Flag Count | H3: Compliance Rate (%) | I3: Risk Level
A4: P001 | B4: Margaret Allen | C4: Pension | D4: =SUMIF('Payment Log'!A:A,A4,'Payment Log'!F:F) | E4: =SUMIF('Payment Log'!A:A,A4,'Payment Log'!G:G) | F4: =E4-D4 | G4: =COUNTIFS('Payment Log'!A:A,A4,'Payment Log'!I:I,"<>Paid") | H4: =IFERROR(1-G4/12,0) | I4: =IF(G4>=3,"HIGH",IF(G4>=1,"MEDIUM","LOW"))
A5: P002 | B5: Robert Nguyen | C5: Pension | D5: =SUMIF('Payment Log'!A:A,A5,'Payment Log'!F:F) | E5: =SUMIF('Payment Log'!A:A,A5,'Payment Log'!G:G) | F5: =E5-D5 | G5: =COUNTIFS('Payment Log'!A:A,A5,'Payment Log'!I:I,"<>Paid") | H5: =IFERROR(1-G5/12,0) | I5: =IF(G5>=3,"HIGH",IF(G5>=1,"MEDIUM","LOW"))
A6: P003 | B6: Susan Park | C6: Allowance | D6: =SUMIF('Payment Log'!A:A,A6,'Payment Log'!F:F) | E6: =SUMIF('Payment Log'!A:A,A6,'Payment Log'!G:G) | F6: =E6-D6 | G6: =COUNTIFS('Payment Log'!A:A,A6,'Payment Log'!I:I,"<>Paid") | H6: =IFERROR(1-G6/12,0) | I6: =IF(G6>=3,"HIGH",IF(G6>=1,"MEDIUM","LOW"))
A7: P004 | B7: David Kim | C7: Pension | D7: =SUMIF('Payment Log'!A:A,A7,'Payment Log'!F:F) | E7: =SUMIF('Payment Log'!A:A,A7,'Payment Log'!G:G) | F7: =E7-D7 | G7: =COUNTIFS('Payment Log'!A:A,A7,'Payment Log'!I:I,"<>Paid") | H7: =IFERROR(1-G7/12,0) | I7: =IF(G7>=3,"HIGH",IF(G7>=1,"MEDIUM","LOW"))
A8: P005 | B8: Linda Tremblay | C8: Allowance | D8: =SUMIF('Payment Log'!A:A,A8,'Payment Log'!F:F) | E8: =SUMIF('Payment Log'!A:A,A8,'Payment Log'!G:G) | F8: =E8-D8 | G8: =COUNTIFS('Payment Log'!A:A,A8,'Payment Log'!I:I,"<>Paid") | H8: =IFERROR(1-G8/12,0) | I8: =IF(G8>=3,"HIGH",IF(G8>=1,"MEDIUM","LOW"))
A9: P006 | B9: James Wilson | C9: Pension | D9: =SUMIF('Payment Log'!A:A,A9,'Payment Log'!F:F) | E9: =SUMIF('Payment Log'!A:A,A9,'Payment Log'!G:G) | F9: =E9-D9 | G9: =COUNTIFS('Payment Log'!A:A,A9,'Payment Log'!I:I,"<>Paid") | H9: =IFERROR(1-G9/12,0) | I9: =IF(G9>=3,"HIGH",IF(G9>=1,"MEDIUM","LOW"))
A10: P007 | B10: Patricia Moore | C10: Allowance | D10: =SUMIF('Payment Log'!A:A,A10,'Payment Log'!F:F) | E10: =SUMIF('Payment Log'!A:A,A10,'Payment Log'!G:G) | F10: =E10-D10 | G10: =COUNTIFS('Payment Log'!A:A,A10,'Payment Log'!I:I,"<>Paid") | H10: =IFERROR(1-G10/12,0) | I10: =IF(G10>=3,"HIGH",IF(G10>=1,"MEDIUM","LOW"))
A11: P008 | B11: Michael Scott | C11: Pension | D11: =SUMIF('Payment Log'!A:A,A11,'Payment Log'!F:F) | E11: =SUMIF('Payment Log'!A:A,A11,'Payment Log'!G:G) | F11: =E11-D11 | G11: =COUNTIFS('Payment Log'!A:A,A11,'Payment Log'!I:I,"<>Paid") | H11: =IFERROR(1-G11/12,0) | I11: =IF(G11>=3,"HIGH",IF(G11>=1,"MEDIUM","LOW"))
A12: P009 | B12: Barbara Lee | C12: Pension | D12: =SUMIF('Payment Log'!A:A,A12,'Payment Log'!F:F) | E12: =SUMIF('Payment Log'!A:A,A12,'Payment Log'!G:G) | F12: =E12-D12 | G12: =COUNTIFS('Payment Log'!A:A,A12,'Payment Log'!I:I,"<>Paid") | H12: =IFERROR(1-G12/12,0) | I12: =IF(G12>=3,"HIGH",IF(G12>=1,"MEDIUM","LOW"))
A13: P010 | B13: William Chen | C13: Allowance | D13: =SUMIF('Payment Log'!A:A,A13,'Payment Log'!F:F) | E13: =SUMIF('Payment Log'!A:A,A13,'Payment Log'!G:G) | F13: =E13-D13 | G13: =COUNTIFS('Payment Log'!A:A,A13,'Payment Log'!I:I,"<>Paid") | H13: =IFERROR(1-G13/12,0) | I13: =IF(G13>=3,"HIGH",IF(G13>=1,"MEDIUM","LOW"))
A14: P011 | B14: Elizabeth Brown | C14: Pension | D14: =SUMIF('Payment Log'!A:A,A14,'Payment Log'!F:F) | E14: =SUMIF('Payment Log'!A:A,A14,'Payment Log'!G:G) | F14: =E14-D14 | G14: =COUNTIFS('Payment Log'!A:A,A14,'Payment Log'!I:I,"<>Paid") | H14: =IFERROR(1-G14/12,0) | I14: =IF(G14>=3,"HIGH",IF(G14>=1,"MEDIUM","LOW"))
A15: P012 | B15: Richard Davis | C15: Allowance | D15: =SUMIF('Payment Log'!A:A,A15,'Payment Log'!F:F) | E15: =SUMIF('Payment Log'!A:A,A15,'Payment Log'!G:G) | F15: =E15-D15 | G15: =COUNTIFS('Payment Log'!A:A,A15,'Payment Log'!I:I,"<>Paid") | H15: =IFERROR(1-G15/12,0) | I15: =IF(G15>=3,"HIGH",IF(G15>=1,"MEDIUM","LOW"))
... A18: P015 | B18: Maria Thompson | C18: Allowance | D18: =SUMIF('Payment Log'!A:A,A18,'Payment Log'!F:F) | E18: =SUMIF('Payment Log'!A:A,A18,'Payment Log'!G:G) | F18: =E18-D18 | G18: =COUNTIFS('Payment Log'!A:A,A18,'Payment Log'!I:I,"<>Paid") | H18: =IFERROR(1-G18/12,0) | I18: =IF(G18>=3,"HIGH",IF(G18>=1,"MEDIUM","LOW"))
A19: TOTALS | D19: =SUM(D4:D18) | E19: =SUM(E4:E18) | F19: =SUM(F4:F18) | G19: =SUM(G4:G18)

Sheet Monthly Dashboard
A1: Monthly Payment Dashboard — 2024
A3: Month | B3: Month # | C3: Total Expected ($) | D3: Total Actual ($) | E3: Total Discrepancy ($) | F3: Payments Made | G3: Flags | H3: Compliance Rate (%) | K3: Status | L3: Count
A4: Jan | B4: 1 | C4: =SUMIF('Payment Log'!E:E,B4,'Payment Log'!F:F) | D4: =SUMIF('Payment Log'!E:E,B4,'Payment Log'!G:G) | E4: =D4-C4 | F4: =COUNTIFS('Payment Log'!E:E,B4,'Payment Log'!I:I,"Paid") | G4: =COUNTIFS('Payment Log'!E:E,B4,'Payment Log'!I:I,"<>Paid") | H4: =IFERROR(F4/(F4+G4),0) | K4: Paid | L4: =COUNTIF('Payment Log'!I:I,"Paid")
A5: Feb | B5: 2 | C5: =SUMIF('Payment Log'!E:E,B5,'Payment Log'!F:F) | D5: =SUMIF('Payment Log'!E:E,B5,'Payment Log'!G:G) | E5: =D5-C5 | F5: =COUNTIFS('Payment Log'!E:E,B5,'Payment Log'!I:I,"Paid") | G5: =COUNTIFS('Payment Log'!E:E,B5,'Payment Log'!I:I,"<>Paid") | H5: =IFERROR(F5/(F5+G5),0) | K5: Late | L5: =COUNTIF('Payment Log'!I:I,"Late")
A6: Mar | B6: 3 | C6: =SUMIF('Payment Log'!E:E,B6,'Payment Log'!F:F) | D6: =SUMIF('Payment Log'!E:E,B6,'Payment Log'!G:G) | E6: =D6-C6 | F6: =COUNTIFS('Payment Log'!E:E,B6,'Payment Log'!I:I,"Paid") | G6: =COUNTIFS('Payment Log'!E:E,B6,'Payment Log'!I:I,"<>Paid") | H6: =IFERROR(F6/(F6+G6),0) | K6: Missed | L6: =COUNTIF('Payment Log'!I:I,"Missed")
A7: Apr | B7: 4 | C7: =SUMIF('Payment Log'!E:E,B7,'Payment Log'!F:F) | D7: =SUMIF('Payment Log'!E:E,B7,'Payment Log'!G:G) | E7: =D7-C7 | F7: =COUNTIFS('Payment Log'!E:E,B7,'Payment Log'!I:I,"Paid") | G7: =COUNTIFS('Payment Log'!E:E,B7,'Payment Log'!I:I,"<>Paid") | H7: =IFERROR(F7/(F7+G7),0) | K7: Under Review | L7: =COUNTIF('Payment Log'!I:I,"Under Review")
A8: May | B8: 5 | C8: =SUMIF('Payment Log'!E:E,B8,'Payment Log'!F:F) | D8: =SUMIF('Payment Log'!E:E,B8,'Payment Log'!G:G) | E8: =D8-C8 | F8: =COUNTIFS('Payment Log'!E:E,B8,'Payment Log'!I:I,"Paid") | G8: =COUNTIFS('Payment Log'!E:E,B8,'Payment Log'!I:I,"<>Paid") | H8: =IFERROR(F8/(F8+G8),0) | K8: Discrepancy | L8: =COUNTIF('Payment Log'!I:I,"Discrepancy")
A9: Jun | B9: 6 | C9: =SUMIF('Payment Log'!E:E,B9,'Payment Log'!F:F) | D9: =SUMIF('Payment Log'!E:E,B9,'Payment Log'!G:G) | E9: =D9-C9 | F9: =COUNTIFS('Payment Log'!E:E,B9,'Payment Log'!I:I,"Paid") | G9: =COUNTIFS('Payment Log'!E:E,B9,'Payment Log'!I:I,"<>Paid") | H9: =IFERROR(F9/(F9+G9),0)
A10: Jul | B10: 7 | C10: =SUMIF('Payment Log'!E:E,B10,'Payment Log'!F:F) | D10: =SUMIF('Payment Log'!E:E,B10,'Payment Log'!G:G) | E10: =D10-C10 | F10: =COUNTIFS('Payment Log'!E:E,B10,'Payment Log'!I:I,"Paid") | G10: =COUNTIFS('Payment Log'!E:E,B10,'Payment Log'!I:I,"<>Paid") | H10: =IFERROR(F10/(F10+G10),0)
A11: Aug | B11: 8 | C11: =SUMIF('Payment Log'!E:E,B11,'Payment Log'!F:F) | D11: =SUMIF('Payment Log'!E:E,B11,'Payment Log'!G:G) | E11: =D11-C11 | F11: =COUNTIFS('Payment Log'!E:E,B11,'Payment Log'!I:I,"Paid") | G11: =COUNTIFS('Payment Log'!E:E,B11,'Payment Log'!I:I,"<>Paid") | H11: =IFERROR(F11/(F11+G11),0)
A12: Sep | B12: 9 | C12: =SUMIF('Payment Log'!E:E,B12,'Payment Log'!F:F) | D12: =SUMIF('Payment Log'!E:E,B12,'Payment Log'!G:G) | E12: =D12-C12 | F12: =COUNTIFS('Payment Log'!E:E,B12,'Payment Log'!I:I,"Paid") | G12: =COUNTIFS('Payment Log'!E:E,B12,'Payment Log'!I:I,"<>Paid") | H12: =IFERROR(F12/(F12+G12),0)
A13: Oct | B13: 10 | C13: =SUMIF('Payment Log'!E:E,B13,'Payment Log'!F:F) | D13: =SUMIF('Payment Log'!E:E,B13,'Payment Log'!G:G) | E13: =D13-C13 | F13: =COUNTIFS('Payment Log'!E:E,B13,'Payment Log'!I:I,"Paid") | G13: =COUNTIFS('Payment Log'!E:E,B13,'Payment Log'!I:I,"<>Paid") | H13: =IFERROR(F13/(F13+G13),0)
A14: Nov | B14: 11 | C14: =SUMIF('Payment Log'!E:E,B14,'Payment Log'!F:F) | D14: =SUMIF('Payment Log'!E:E,B14,'Payment Log'!G:G) | E14: =D14-C14 | F14: =COUNTIFS('Payment Log'!E:E,B14,'Payment Log'!I:I,"Paid") | G14: =COUNTIFS('Payment Log'!E:E,B14,'Payment Log'!I:I,"<>Paid") | H14: =IFERROR(F14/(F14+G14),0)
A15: Dec | B15: 12 | C15: =SUMIF('Payment Log'!E:E,B15,'Payment Log'!F:F) | D15: =SUMIF('Payment Log'!E:E,B15,'Payment Log'!G:G) | E15: =D15-C15 | F15: =COUNTIFS('Payment Log'!E:E,B15,'Payment Log'!I:I,"Paid") | G15: =COUNTIFS('Payment Log'!E:E,B15,'Payment Log'!I:I,"<>Paid") | H15: =IFERROR(F15/(F15+G15),0)

Sheet Discrepancy Register
A1: Discrepancy Register — Non-Paid Transactions Review Queue
A2: Use dropdown filters to sort by Month, Status, or Claimant. Update 'Resolution' column as cases are cleared.
A3: # | B3: Claimant ID | C3: Claimant Name | D3: Type | E3: Month | F3: Expected ($) | G3: Actual ($) | H3: Discrepancy ($) | I3: Status | J3: Reviewed By | K3: Resolution
A4: 1 | B4: P001 | C4: Margaret Allen | D4: Pension | E4: Mar | F4: 2122.49 | G4: 1141.16 | H4: -981.33 | I4: Under Review | J4: EMP05 | K4: Pending
A5: 2 | B5: P001 | C5: Margaret Allen | D5: Pension | E5: Jul | F5: 2122.49 | G5: 2122.49 | H5: 0 | I5: Late | J5: EMP01 | K5: Pending
A6: 3 | B6: P001 | C6: Margaret Allen | D6: Pension | E6: Sep | F6: 2122.49 | G6: 1421.66 | H6: -700.83 | I6: Under Review | J6: EMP05 | K6: Pending
A7: 4 | B7: P001 | C7: Margaret Allen | D7: Pension | E7: Nov | F7: 2122.49 | G7: 2837.61 | H7: 715.12 | I7: Discrepancy | J7: EMP05 | K7: Pending
A8: 5 | B8: P001 | C8: Margaret Allen | D8: Pension | E8: Dec | F8: 2122.49 | G8: 2545.23 | H8: 422.74 | I8: Discrepancy | J8: EMP02 | K8: Pending
A9: 6 | B9: P002 | C9: Robert Nguyen | D9: Pension | E9: Feb | F9: 2000.5 | G9: 2000.5 | H9: 0 | I9: Late | J9: EMP02 | K9: Pending
A10: 7 | B10: P002 | C10: Robert Nguyen | D10: Pension | E10: Mar | F10: 2000.5 | G10: 1094.51 | H10: -905.99 | I10: Under Review | J10: EMP03 | K10: Pending
A11: 8 | B11: P002 | C11: Robert Nguyen | D11: Pension | E11: Apr | F11: 2000.5 | G11: 1653.31 | H11: -347.19 | I11: Under Review | J11: EMP02 | K11: Pending
A12: 9 | B12: P002 | C12: Robert Nguyen | D12: Pension | E12: Jun | F12: 2000.5 | G12: 2520.09 | H12: 519.59 | I12: Discrepancy | J12: EMP03 | K12: Pending
A13: 10 | B13: P002 | C13: Robert Nguyen | D13: Pension | E13: Nov | F13: 2000.5 | G13: 1342.41 | H13: -658.09 | I13: Under Review | J13: EMP03 | K13: Pending
A14: 11 | B14: P002 | C14: Robert Nguyen | D14: Pension | E14: Dec | F14: 2000.5 | G14: 0 | H14: -2000.5 | I14: Missed | J14: EMP05 | K14: Pending
A15: 12 | B15: P003 | C15: Susan Park | D15: Allowance | E15: Apr | F15: 1572.8 | G15: 1848.14 | H15: 275.34 | I15: Discrepancy | J15: EMP04 | K15: Pending
... A81: 78 | B81: P015 | C81: Maria Thompson | D81: Allowance | E81: Dec | F81: 1368.68 | G81: 1025.92 | H81: -342.76 | I81: Under Review | J81: EMP05 | K81: Pending
